2021-11-03 00:24:30,556 (41093/MainThread) litecli.main ERROR - sql: 'SELECT TABLE clover_event', error: OperationalError('near "TABLE": syntax error')
2021-11-03 00:24:30,557 (41093/MainThread) litecli.main ERROR - traceback: 'Traceback (most recent call last):\n  File "/usr/lib/python3.9/site-packages/litecli/sqlexecute.py", line 122, in run\n    for result in special.execute(cur, sql):\n  File "/usr/lib/python3.9/site-packages/litecli/packages/special/main.py", line 109, in execute\n    raise CommandNotFound\nlitecli.packages.special.main.CommandNotFound\n\nDuring handling of the above exception, another exception occurred:\n\nTraceback (most recent call last):\n  File "/usr/lib/python3.9/site-packages/litecli/main.py", line 441, in one_iteration\n    for title, cur, headers, status in res:\n  File "/usr/lib/python3.9/site-packages/litecli/sqlexecute.py", line 126, in run\n    cur.execute(sql)\nsqlite3.OperationalError: near "TABLE": syntax error\n'
2021-11-03 01:24:39,458 (41093/MainThread) litecli.main ERROR - sql: 'cls', error: OperationalError('near "cls": syntax error')
2021-11-03 01:24:39,459 (41093/MainThread) litecli.main ERROR - traceback: 'Traceback (most recent call last):\n  File "/usr/lib/python3.9/site-packages/litecli/sqlexecute.py", line 122, in run\n    for result in special.execute(cur, sql):\n  File "/usr/lib/python3.9/site-packages/litecli/packages/special/main.py", line 109, in execute\n    raise CommandNotFound\nlitecli.packages.special.main.CommandNotFound\n\nDuring handling of the above exception, another exception occurred:\n\nTraceback (most recent call last):\n  File "/usr/lib/python3.9/site-packages/litecli/main.py", line 441, in one_iteration\n    for title, cur, headers, status in res:\n  File "/usr/lib/python3.9/site-packages/litecli/sqlexecute.py", line 126, in run\n    cur.execute(sql)\nsqlite3.OperationalError: near "cls": syntax error\n'
2021-11-03 01:24:40,937 (41093/MainThread) litecli.main ERROR - sql: 'clear', error: OperationalError('near "clear": syntax error')
2021-11-03 01:24:40,937 (41093/MainThread) litecli.main ERROR - traceback: 'Traceback (most recent call last):\n  File "/usr/lib/python3.9/site-packages/litecli/sqlexecute.py", line 122, in run\n    for result in special.execute(cur, sql):\n  File "/usr/lib/python3.9/site-packages/litecli/packages/special/main.py", line 109, in execute\n    raise CommandNotFound\nlitecli.packages.special.main.CommandNotFound\n\nDuring handling of the above exception, another exception occurred:\n\nTraceback (most recent call last):\n  File "/usr/lib/python3.9/site-packages/litecli/main.py", line 441, in one_iteration\n    for title, cur, headers, status in res:\n  File "/usr/lib/python3.9/site-packages/litecli/sqlexecute.py", line 126, in run\n    cur.execute(sql)\nsqlite3.OperationalError: near "clear": syntax error\n'
2021-11-03 05:43:00,324 (250987/MainThread) litecli.main ERROR - sql: 'SELECT * FROM clover_event', error: OperationalError('no such table: clover_event')
2021-11-03 05:43:00,326 (250987/MainThread) litecli.main ERROR - traceback: 'Traceback (most recent call last):\n  File "/usr/lib/python3.9/site-packages/litecli/sqlexecute.py", line 122, in run\n    for result in special.execute(cur, sql):\n  File "/usr/lib/python3.9/site-packages/litecli/packages/special/main.py", line 109, in execute\n    raise CommandNotFound\nlitecli.packages.special.main.CommandNotFound\n\nDuring handling of the above exception, another exception occurred:\n\nTraceback (most recent call last):\n  File "/usr/lib/python3.9/site-packages/litecli/main.py", line 441, in one_iteration\n    for title, cur, headers, status in res:\n  File "/usr/lib/python3.9/site-packages/litecli/sqlexecute.py", line 126, in run\n    cur.execute(sql)\nsqlite3.OperationalError: no such table: clover_event\n'
2021-11-03 05:43:05,959 (250987/MainThread) litecli.main ERROR - sql: 'SELECT * FROM clover_event', error: OperationalError('no such table: clover_event')
2021-11-03 05:43:05,959 (250987/MainThread) litecli.main ERROR - traceback: 'Traceback (most recent call last):\n  File "/usr/lib/python3.9/site-packages/litecli/sqlexecute.py", line 122, in run\n    for result in special.execute(cur, sql):\n  File "/usr/lib/python3.9/site-packages/litecli/packages/special/main.py", line 109, in execute\n    raise CommandNotFound\nlitecli.packages.special.main.CommandNotFound\n\nDuring handling of the above exception, another exception occurred:\n\nTraceback (most recent call last):\n  File "/usr/lib/python3.9/site-packages/litecli/main.py", line 441, in one_iteration\n    for title, cur, headers, status in res:\n  File "/usr/lib/python3.9/site-packages/litecli/sqlexecute.py", line 126, in run\n    cur.execute(sql)\nsqlite3.OperationalError: no such table: clover_event\n'
2021-11-03 05:43:12,428 (252812/MainThread) litecli.main ERROR - sql: 'SELECT * FROM clover_event', error: OperationalError('no such table: clover_event')
2021-11-03 05:43:12,430 (252812/MainThread) litecli.main ERROR - traceback: 'Traceback (most recent call last):\n  File "/usr/lib/python3.9/site-packages/litecli/sqlexecute.py", line 122, in run\n    for result in special.execute(cur, sql):\n  File "/usr/lib/python3.9/site-packages/litecli/packages/special/main.py", line 109, in execute\n    raise CommandNotFound\nlitecli.packages.special.main.CommandNotFound\n\nDuring handling of the above exception, another exception occurred:\n\nTraceback (most recent call last):\n  File "/usr/lib/python3.9/site-packages/litecli/main.py", line 441, in one_iteration\n    for title, cur, headers, status in res:\n  File "/usr/lib/python3.9/site-packages/litecli/sqlexecute.py", line 126, in run\n    cur.execute(sql)\nsqlite3.OperationalError: no such table: clover_event\n'
2021-11-03 05:50:08,888 (252812/MainThread) litecli.main ERROR - sql: 'SELECT * FROM clover_eventmodel', error: OperationalError('no such table: clover_eventmodel')
2021-11-03 05:50:08,889 (252812/MainThread) litecli.main ERROR - traceback: 'Traceback (most recent call last):\n  File "/usr/lib/python3.9/site-packages/litecli/sqlexecute.py", line 122, in run\n    for result in special.execute(cur, sql):\n  File "/usr/lib/python3.9/site-packages/litecli/packages/special/main.py", line 109, in execute\n    raise CommandNotFound\nlitecli.packages.special.main.CommandNotFound\n\nDuring handling of the above exception, another exception occurred:\n\nTraceback (most recent call last):\n  File "/usr/lib/python3.9/site-packages/litecli/main.py", line 441, in one_iteration\n    for title, cur, headers, status in res:\n  File "/usr/lib/python3.9/site-packages/litecli/sqlexecute.py", line 126, in run\n    cur.execute(sql)\nsqlite3.OperationalError: no such table: clover_eventmodel\n'
2021-11-03 06:59:29,675 (253246/MainThread) litecli.main ERROR - sql: 'SELECT * FROM clover_model', error: OperationalError('no such table: clover_model')
2021-11-03 06:59:29,676 (253246/MainThread) litecli.main ERROR - traceback: 'Traceback (most recent call last):\n  File "/usr/lib/python3.9/site-packages/litecli/sqlexecute.py", line 122, in run\n    for result in special.execute(cur, sql):\n  File "/usr/lib/python3.9/site-packages/litecli/packages/special/main.py", line 109, in execute\n    raise CommandNotFound\nlitecli.packages.special.main.CommandNotFound\n\nDuring handling of the above exception, another exception occurred:\n\nTraceback (most recent call last):\n  File "/usr/lib/python3.9/site-packages/litecli/main.py", line 441, in one_iteration\n    for title, cur, headers, status in res:\n  File "/usr/lib/python3.9/site-packages/litecli/sqlexecute.py", line 126, in run\n    cur.execute(sql)\nsqlite3.OperationalError: no such table: clover_model\n'
2021-11-04 19:54:13,776 (31961/MainThread) litecli.main ERROR - sql: 'ls', error: OperationalError('near "ls": syntax error')
2021-11-04 19:54:13,777 (31961/MainThread) litecli.main ERROR - traceback: 'Traceback (most recent call last):\n  File "/usr/lib/python3.9/site-packages/litecli/sqlexecute.py", line 122, in run\n    for result in special.execute(cur, sql):\n  File "/usr/lib/python3.9/site-packages/litecli/packages/special/main.py", line 109, in execute\n    raise CommandNotFound\nlitecli.packages.special.main.CommandNotFound\n\nDuring handling of the above exception, another exception occurred:\n\nTraceback (most recent call last):\n  File "/usr/lib/python3.9/site-packages/litecli/main.py", line 441, in one_iteration\n    for title, cur, headers, status in res:\n  File "/usr/lib/python3.9/site-packages/litecli/sqlexecute.py", line 126, in run\n    cur.execute(sql)\nsqlite3.OperationalError: near "ls": syntax error\n'
2021-11-05 01:59:12,191 (106505/MainThread) litecli.main ERROR - sql: 'asd\n\n\n;', error: OperationalError('near "asd": syntax error')
2021-11-05 01:59:12,193 (106505/MainThread) litecli.main ERROR - traceback: 'Traceback (most recent call last):\n  File "/usr/lib/python3.9/site-packages/litecli/sqlexecute.py", line 122, in run\n    for result in special.execute(cur, sql):\n  File "/usr/lib/python3.9/site-packages/litecli/packages/special/main.py", line 109, in execute\n    raise CommandNotFound\nlitecli.packages.special.main.CommandNotFound\n\nDuring handling of the above exception, another exception occurred:\n\nTraceback (most recent call last):\n  File "/usr/lib/python3.9/site-packages/litecli/main.py", line 441, in one_iteration\n    for title, cur, headers, status in res:\n  File "/usr/lib/python3.9/site-packages/litecli/sqlexecute.py", line 126, in run\n    cur.execute(sql)\nsqlite3.OperationalError: near "asd": syntax error\n'
2021-11-05 02:02:56,789 (106810/MainThread) litecli.main ERROR - sql: 'ALL clover_eventmodel;', error: OperationalError('near "ALL": syntax error')
2021-11-05 02:02:56,791 (106810/MainThread) litecli.main ERROR - traceback: 'Traceback (most recent call last):\n  File "/usr/lib/python3.9/site-packages/litecli/sqlexecute.py", line 122, in run\n    for result in special.execute(cur, sql):\n  File "/usr/lib/python3.9/site-packages/litecli/packages/special/main.py", line 109, in execute\n    raise CommandNotFound\nlitecli.packages.special.main.CommandNotFound\n\nDuring handling of the above exception, another exception occurred:\n\nTraceback (most recent call last):\n  File "/usr/lib/python3.9/site-packages/litecli/main.py", line 441, in one_iteration\n    for title, cur, headers, status in res:\n  File "/usr/lib/python3.9/site-packages/litecli/sqlexecute.py", line 126, in run\n    cur.execute(sql)\nsqlite3.OperationalError: near "ALL": syntax error\n'
2021-11-05 02:04:02,623 (106810/MainThread) litecli.main ERROR - sql: 'ALL clover_eventmodel\n;', error: OperationalError('near "ALL": syntax error')
2021-11-05 02:04:02,623 (106810/MainThread) litecli.main ERROR - traceback: 'Traceback (most recent call last):\n  File "/usr/lib/python3.9/site-packages/litecli/sqlexecute.py", line 122, in run\n    for result in special.execute(cur, sql):\n  File "/usr/lib/python3.9/site-packages/litecli/packages/special/main.py", line 109, in execute\n    raise CommandNotFound\nlitecli.packages.special.main.CommandNotFound\n\nDuring handling of the above exception, another exception occurred:\n\nTraceback (most recent call last):\n  File "/usr/lib/python3.9/site-packages/litecli/main.py", line 441, in one_iteration\n    for title, cur, headers, status in res:\n  File "/usr/lib/python3.9/site-packages/litecli/sqlexecute.py", line 126, in run\n    cur.execute(sql)\nsqlite3.OperationalError: near "ALL": syntax error\n'
2021-11-05 02:04:07,143 (107555/MainThread) litecli.main ERROR - sql: 'ALL clover_eventmodel', error: OperationalError('near "ALL": syntax error')
2021-11-05 02:04:07,145 (107555/MainThread) litecli.main ERROR - traceback: 'Traceback (most recent call last):\n  File "/usr/lib/python3.9/site-packages/litecli/sqlexecute.py", line 122, in run\n    for result in special.execute(cur, sql):\n  File "/usr/lib/python3.9/site-packages/litecli/packages/special/main.py", line 109, in execute\n    raise CommandNotFound\nlitecli.packages.special.main.CommandNotFound\n\nDuring handling of the above exception, another exception occurred:\n\nTraceback (most recent call last):\n  File "/usr/lib/python3.9/site-packages/litecli/main.py", line 441, in one_iteration\n    for title, cur, headers, status in res:\n  File "/usr/lib/python3.9/site-packages/litecli/sqlexecute.py", line 126, in run\n    cur.execute(sql)\nsqlite3.OperationalError: near "ALL": syntax error\n'
2021-11-05 02:04:28,407 (107621/MainThread) litecli.main ERROR - sql: 'ALL clover_eventmodel', error: OperationalError('near "ALL": syntax error')
2021-11-05 02:04:28,409 (107621/MainThread) litecli.main ERROR - traceback: 'Traceback (most recent call last):\n  File "/usr/lib/python3.9/site-packages/litecli/sqlexecute.py", line 122, in run\n    for result in special.execute(cur, sql):\n  File "/usr/lib/python3.9/site-packages/litecli/packages/special/main.py", line 109, in execute\n    raise CommandNotFound\nlitecli.packages.special.main.CommandNotFound\n\nDuring handling of the above exception, another exception occurred:\n\nTraceback (most recent call last):\n  File "/usr/lib/python3.9/site-packages/litecli/main.py", line 441, in one_iteration\n    for title, cur, headers, status in res:\n  File "/usr/lib/python3.9/site-packages/litecli/sqlexecute.py", line 126, in run\n    cur.execute(sql)\nsqlite3.OperationalError: near "ALL": syntax error\n'
